<?xml version='1.0'?>
<sdf version='1.4'>
  <model name="simple_robot">
    <static>false</static>
    <link name='chassis'>
      <pose>0 0 .1 0 0 0</pose>
      <inertial>
        <mass>10.0</mass>
        <inertia>
          <!-- for a box: ixx = 0.083 * mass * (y*y + z*z) -->
          <ixx>0.041500</ixx>
          <!-- for a box: ixy = 0 -->
          <ixy>0.0</ixy>
          <!-- for a box: ixz = 0 -->
          <ixz>0.0</ixz>
          <!-- for a box: iyy = 0.083 * mass * (x*x + z*z) -->
          <iyy>0.141100</iyy>
          <!-- for a box: iyz = 0 -->
          <iyz>0.0</iyz>
          <!-- for a box: izz = 0.083 * mass * (x*x + y*y) -->
          <izz>0.166000</izz>
        </inertia>
      </inertial>
      <collision name='collision'>
        <geometry>
          <box>
            <size>.4 .2 .1</size>
          </box>
        </geometry>
      </collision>
      <visual name='visual'>
        <geometry>
          <box>
            <size>.4 .2 .1</size>
          </box>
        </geometry>
      </visual>

      <collision name='caster_collision'>
        <pose>-0.15 0 -0.05 0 0 0</pose>
        <geometry>
          <sphere>
            <radius>.05</radius>
          </sphere>
        </geometry>
        <surface>
          <friction>
            <ode>
              <mu>0</mu>
              <mu2>0</mu2>
              <slip1>1.0</slip1>
              <slip2>1.0</slip2>
            </ode>
          </friction>
        </surface>
      </collision>
      <visual name='caster_visual'>
        <pose>-0.15 0 -0.05 0 0 0</pose>
        <geometry>
          <sphere>
            <radius>.05</radius>
          </sphere>
        </geometry>
      </visual>
    </link>

    <link name="right_wheel">
      <pose>0.1 -0.13 0.1 0 1.5707 1.5707</pose>
      <collision name="collision">
        <geometry>
          <cylinder>
            <radius>.1</radius>
            <length>.03</length>
          </cylinder>
        </geometry>
      </collision>
      <visual name="visual">
        <geometry>
          <cylinder>
            <radius>.1</radius>
            <length>.05</length>
          </cylinder>
        </geometry>
      </visual>
    </link>
    <link name="left_wheel">
      <pose>0.1 0.13 0.1 0 1.5707 1.5707</pose>
      <collision name="collision">
        <geometry>
          <cylinder>
            <radius>.1</radius>
            <length>.03</length>
          </cylinder>
        </geometry>
      </collision>
      <visual name="visual">
        <geometry>
          <cylinder>
            <radius>.1</radius>
            <length>.05</length>
          </cylinder>
        </geometry>
      </visual>
    </link>

    <joint type="revolute" name="right_wheel_hinge">
      <pose>0 0 0.03 0 0 0</pose>
      <child>right_wheel</child>
      <parent>chassis</parent>
      <axis>
        <xyz>0 1 0</xyz>
      </axis>
    </joint>
    <joint type="revolute" name="left_wheel_hinge">
      <pose>0 0 -0.03 0 0 0</pose>
      <child>left_wheel</child>
      <parent>chassis</parent>
      <axis>
        <xyz>0 1 0</xyz>
      </axis>
    </joint>

    <include>
      <uri>model://2d_laser</uri>
      <pose>0.2 0 0.2 0 0 0</pose>
    </include>
    <joint name="2d_laser_joint" type="fixed">
      <child>2d_laser::link</child>
      <parent>chassis</parent>
    </joint>

    <plugin name="object_controller" filename="libgazebo_ros_planar_move.so">
      <commandTopic>cmd_vel</commandTopic>
      <odometryTopic>odom</odometryTopic>
      <odometryFrame>odom</odometryFrame>
      <odometryRate>20.0</odometryRate>
      <robotBaseFrame>chassis</robotBaseFrame>
    </plugin>
  </model>
</sdf>
